<?xml version="1.0" encoding="utf-8"?>
<robot
  name="Leg_assy">
  <link
    name="base_link">
    <inertial>
      <origin
        xyz="4.18417382268018E-18 0.163442278735188 0.056349184966193"
        rpy="0 0 0" />
      <mass
        value="16.5734400005168" />
      <inertia
        ixx="0.599382842220564"
        ixy="3.31258999878971E-19"
        ixz="-9.5745694021733E-19"
        iyy="0.314369255307197"
        iyz="0.0543747383319666"
        izz="0.69835214185245" />
    </inertial>
    <visual>
      <origin
        xyz="0 0 0"
        rpy="0 0 0" />
      <geometry>
        <mesh
          filename="package://Leg_assy/meshes/base_link.STL" />
      </geometry>
      <material
        name="">
        <color
          rgba="0.898039215686275 0.917647058823529 0.929411764705882 1" />
      </material>
    </visual>
    <collision>
      <origin
        xyz="0 0 0"
        rpy="0 0 0" />
      <geometry>
        <mesh
          filename="package://Leg_assy/meshes/base_link.STL" />
      </geometry>
    </collision>
  </link>
  <link
    name="L1">
    <inertial>
      <origin
        xyz="2.36400915256451E-06 0.0399905182025553 0.0431593419729566"
        rpy="0 0 0" />
      <mass
        value="1.01682415477747" />
      <inertia
        ixx="0.000888667138585407"
        ixy="5.96051078342825E-08"
        ixz="2.85100543877057E-09"
        iyy="0.00102361992372075"
        iyz="-1.14275040492286E-08"
        izz="0.00107797593182006" />
    </inertial>
    <visual>
      <origin
        xyz="0 0 0"
        rpy="0 0 0" />
      <geometry>
        <mesh
          filename="package://Leg_assy/meshes/L1.STL" />
      </geometry>
      <material
        name="">
        <color
          rgba="0.898039215686275 0.917647058823529 0.929411764705882 1" />
      </material>
    </visual>
    <collision>
      <origin
        xyz="0 0 0"
        rpy="0 0 0" />
      <geometry>
        <mesh
          filename="package://Leg_assy/meshes/L1.STL" />
      </geometry>
    </collision>
  </link>
  <joint
    name="J1"
    type="prismatic">
    <origin
      xyz="0 -0.061213 0.21128"
      rpy="1.5708 0 0" />
    <parent
      link="base_link" />
    <child
      link="L1" />
    <axis
      xyz="0 -1 0" />
    <limit
      lower="0"
      upper="0"
      effort="0"
      velocity="0" />
  </joint>
  <link
    name="L2">
    <inertial>
      <origin
        xyz="0.0577555492395793 0.0248483960703704 -2.77555756156289E-17"
        rpy="0 0 0" />
      <mass
        value="0.358735867858246" />
      <inertia
        ixx="0.000142844334105728"
        ixy="7.36856791102412E-07"
        ixz="-9.82546248751865E-20"
        iyy="0.000894202221209064"
        iyz="2.65909935103524E-20"
        izz="0.000915364185998044" />
    </inertial>
    <visual>
      <origin
        xyz="0 0 0"
        rpy="0 0 0" />
      <geometry>
        <mesh
          filename="package://Leg_assy/meshes/L2.STL" />
      </geometry>
      <material
        name="">
        <color
          rgba="1 1 1 1" />
      </material>
    </visual>
    <collision>
      <origin
        xyz="0 0 0"
        rpy="0 0 0" />
      <geometry>
        <mesh
          filename="package://Leg_assy/meshes/L2.STL" />
      </geometry>
    </collision>
  </link>
  <joint
    name="J2"
    type="continuous">
    <origin
      xyz="0 0.04 0.09"
      rpy="1.5708 0 -0.23244" />
    <parent
      link="L1" />
    <child
      link="L2" />
    <axis
      xyz="0 1 0" />
  </joint>
  <link
    name="L3">
    <inertial>
      <origin
        xyz="-0.081820360738164 0.0187783528182829 1.85004105923703E-08"
        rpy="0 0 0" />
      <mass
        value="0.163006715229028" />
      <inertia
        ixx="1.75272334572335E-05"
        ixy="3.15450583016002E-06"
        ixz="1.86218179383575E-10"
        iyy="0.000219079773110987"
        iyz="-4.68217074040256E-11"
        izz="0.000215227112014871" />
    </inertial>
    <visual>
      <origin
        xyz="0 0 0"
        rpy="0 0 0" />
      <geometry>
        <mesh
          filename="package://Leg_assy/meshes/L3.STL" />
      </geometry>
      <material
        name="">
        <color
          rgba="1 1 1 1" />
      </material>
    </visual>
    <collision>
      <origin
        xyz="0 0 0"
        rpy="0 0 0" />
      <geometry>
        <mesh
          filename="package://Leg_assy/meshes/L3.STL" />
      </geometry>
    </collision>
  </link>
  <joint
    name="J3"
    type="continuous">
    <origin
      xyz="0.15 0.0125 0"
      rpy="3.1416 1.2453 -3.1416" />
    <parent
      link="L2" />
    <child
      link="L3" />
    <axis
      xyz="0 -1 0" />
  </joint>
</robot>
