<?xml version="1.0" encoding="utf-8"?>
<!-- This URDF was automatically created by SolidWorks to URDF Exporter! Originally created by Stephen Brawner (brawner@gmail.com) 
     Commit Version: 1.6.0-4-g7f85cfe  Build Version: 1.6.7995.38578
     For more information, please see http://wiki.ros.org/sw_urdf_exporter -->
<robot
  name="WBR_prototype">
  <link
    name="base_link">
    <inertial>
      <origin
        xyz="-3.35742547264237E-17 -9.11466021782636E-18 1.577370176157E-17"
        rpy="0 0 0" />
      <mass
        value="79.435415621746" />
      <inertia
        ixx="0.936396686083776"
        ixy="2.52034653455517E-17"
        ixz="2.57762713761324E-17"
        iyy="1.67256373747467"
        iyz="6.38678724097504E-17"
        izz="1.48256968665553" />
    </inertial>
    <visual>
      <origin
        xyz="0 0 0"
        rpy="0 0 0" />
      <geometry>
        <mesh
          filename="package://WBR_prototype/meshes/base_link.STL" />
      </geometry>
      <material
        name="">
        <color
          rgba="0.898039215686275 0.917647058823529 0.929411764705882 1" />
      </material>
    </visual>
    <collision>
      <origin
        xyz="0 0 0"
        rpy="0 0 0" />
      <geometry>
        <mesh
          filename="package://WBR_prototype/meshes/base_link.STL" />
      </geometry>
    </collision>
  </link>
  <link
    name="A1_Link">
    <inertial>
      <origin
        xyz="0.0123937238930464 0.0249999999999999 -1.38777878078145E-17"
        rpy="0 0 0" />
      <mass
        value="4.58334450236852" />
      <inertia
        ixx="0.00461060976863761"
        ixy="-8.53506861085946E-18"
        ixz="5.52943107967607E-17"
        iyy="0.0604011849476407"
        iyz="2.35123470896141E-19"
        izz="0.0576287318981151" />
    </inertial>
    <visual>
      <origin
        xyz="0 0 0"
        rpy="0 0 0" />
      <geometry>
        <mesh
          filename="package://WBR_prototype/meshes/A1_Link.STL" />
      </geometry>
      <material
        name="">
        <color
          rgba="0.898039215686275 0.917647058823529 0.929411764705882 1" />
      </material>
    </visual>
    <collision>
      <origin
        xyz="0 0 0"
        rpy="0 0 0" />
      <geometry>
        <mesh
          filename="package://WBR_prototype/meshes/A1_Link.STL" />
      </geometry>
    </collision>
  </link>
  <joint
    name="A1"
    type="fixed">
    <origin
      xyz="0.255 0.18353 -0.098031"
      rpy="0 0.71225 1.5708" />
    <parent
      link="base_link" />
    <child
      link="A1_Link" />
    <axis
      xyz="0 0 0" />
  </joint>
  <link
    name="A15_Link">
    <inertial>
      <origin
        xyz="0.109893824662281 0.025 -1.11022302462516E-16"
        rpy="0 0 0" />
      <mass
        value="4.99934360485206" />
      <inertia
        ixx="0.00335674361919314"
        ixy="-1.8864423194188E-17"
        ixz="1.03324467037869E-16"
        iyy="0.112471776561935"
        iyz="-1.16854134262832E-18"
        izz="0.111109301926735" />
    </inertial>
    <visual>
      <origin
        xyz="0 0 0"
        rpy="0 0 0" />
      <geometry>
        <mesh
          filename="package://WBR_prototype/meshes/A15_Link.STL" />
      </geometry>
      <material
        name="">
        <color
          rgba="0.898039215686275 0.917647058823529 0.929411764705882 1" />
      </material>
    </visual>
    <collision>
      <origin
        xyz="0 0 0"
        rpy="0 0 0" />
      <geometry>
        <mesh
          filename="package://WBR_prototype/meshes/A15_Link.STL" />
      </geometry>
    </collision>
  </link>
  <joint
    name="A15"
    type="fixed">
    <origin
      xyz="0.1924 0.1 -0.34992"
      rpy="3.1416 -1.5491 0" />
    <parent
      link="A1_Link" />
    <child
      link="A15_Link" />
    <axis
      xyz="0 0 0" />
  </joint>
  <link
    name="WR_Link">
    <inertial>
      <origin
        xyz="0 -0.025 5.55111512312578E-17"
        rpy="0 0 0" />
      <mass
        value="3.01810315038832" />
      <inertia
        ixx="0.0122553300870839"
        ixy="1.68518870133883E-34"
        ixz="8.67361737988404E-19"
        iyy="0.0232789295920736"
        iyz="7.37180746360739E-20"
        izz="0.0122553300870839" />
    </inertial>
    <visual>
      <origin
        xyz="0 0 0"
        rpy="0 0 0" />
      <geometry>
        <mesh
          filename="package://WBR_prototype/meshes/WR_Link.STL" />
      </geometry>
      <material
        name="">
        <color
          rgba="0.298039215686275 0.298039215686275 0.298039215686275 1" />
      </material>
    </visual>
    <collision>
      <origin
        xyz="0 0 0"
        rpy="0 0 0" />
      <geometry>
        <mesh
          filename="package://WBR_prototype/meshes/WR_Link.STL" />
      </geometry>
    </collision>
  </link>
  <joint
    name="WR"
    type="continuous">
    <origin
      xyz="-0.15 0.05 0"
      rpy="3.1416 1.218 0" />
    <parent
      link="A15_Link" />
    <child
      link="WR_Link" />
    <axis
      xyz="0 1 0" />
  </joint>
  <link
    name="A2_Link">
    <inertial>
      <origin
        xyz="0.0123937238930463 0.025 4.16333634234434E-17"
        rpy="0 0 0" />
      <mass
        value="4.58334450236852" />
      <inertia
        ixx="0.00461060976863762"
        ixy="3.30199279258287E-18"
        ixz="-4.46691295064028E-17"
        iyy="0.0604011849476407"
        iyz="-6.0525621139655E-19"
        izz="0.0576287318981151" />
    </inertial>
    <visual>
      <origin
        xyz="0 0 0"
        rpy="0 0 0" />
      <geometry>
        <mesh
          filename="package://WBR_prototype/meshes/A2_Link.STL" />
      </geometry>
      <material
        name="">
        <color
          rgba="0.898039215686275 0.917647058823529 0.929411764705882 1" />
      </material>
    </visual>
    <collision>
      <origin
        xyz="0 0 0"
        rpy="0 0 0" />
      <geometry>
        <mesh
          filename="package://WBR_prototype/meshes/A2_Link.STL" />
      </geometry>
    </collision>
  </link>
  <joint
    name="A2"
    type="fixed">
    <origin
      xyz="0.255 -0.18353 -0.098031"
      rpy="3.1416 0.71225 -1.5708" />
    <parent
      link="base_link" />
    <child
      link="A2_Link" />
    <axis
      xyz="0 0 0" />
  </joint>
  <link
    name="A26_Link">
    <inertial>
      <origin
        xyz="0.109893824662281 0.025 -5.55111512312578E-17"
        rpy="0 0 0" />
      <mass
        value="4.99934360485206" />
      <inertia
        ixx="0.00335674361919313"
        ixy="1.04314921672282E-18"
        ixz="-5.68121938382404E-17"
        iyy="0.112471776561935"
        iyz="-2.89320633353585E-19"
        izz="0.111109301926735" />
    </inertial>
    <visual>
      <origin
        xyz="0 0 0"
        rpy="0 0 0" />
      <geometry>
        <mesh
          filename="package://WBR_prototype/meshes/A26_Link.STL" />
      </geometry>
      <material
        name="">
        <color
          rgba="0.898039215686275 0.917647058823529 0.929411764705882 1" />
      </material>
    </visual>
    <collision>
      <origin
        xyz="0 0 0"
        rpy="0 0 0" />
      <geometry>
        <mesh
          filename="package://WBR_prototype/meshes/A26_Link.STL" />
      </geometry>
    </collision>
  </link>
  <joint
    name="A26"
    type="fixed">
    <origin
      xyz="0.1924 0 0.34992"
      rpy="3.1416 1.5491 0" />
    <parent
      link="A2_Link" />
    <child
      link="A26_Link" />
    <axis
      xyz="0 0 0" />
  </joint>
  <link
    name="A3_Link">
    <inertial>
      <origin
        xyz="0.0123937238930464 0.025 0"
        rpy="0 0 0" />
      <mass
        value="4.58334450236852" />
      <inertia
        ixx="0.00461060976863762"
        ixy="-9.72010761066201E-18"
        ixz="6.33174068731535E-17"
        iyy="0.0604011849476408"
        iyz="-5.29351441547726E-19"
        izz="0.0576287318981152" />
    </inertial>
    <visual>
      <origin
        xyz="0 0 0"
        rpy="0 0 0" />
      <geometry>
        <mesh
          filename="package://WBR_prototype/meshes/A3_Link.STL" />
      </geometry>
      <material
        name="">
        <color
          rgba="0.898039215686275 0.917647058823529 0.929411764705882 1" />
      </material>
    </visual>
    <collision>
      <origin
        xyz="0 0 0"
        rpy="0 0 0" />
      <geometry>
        <mesh
          filename="package://WBR_prototype/meshes/A3_Link.STL" />
      </geometry>
    </collision>
  </link>
  <joint
    name="A3"
    type="fixed">
    <origin
      xyz="-0.205 0.183533542805022 -0.0980312942796335"
      rpy="0 0.71225466118791 1.5707963267949" />
    <parent
      link="base_link" />
    <child
      link="A3_Link" />
    <axis
      xyz="0 0 0" />
  </joint>
  <link
    name="A37_Link">
    <inertial>
      <origin
        xyz="0.109893824662281 0.025 -1.11022302462516E-16"
        rpy="0 0 0" />
      <mass
        value="4.99934360485206" />
      <inertia
        ixx="0.00335674361919312"
        ixy="-4.94383568410852E-19"
        ixz="1.2414114874959E-16"
        iyy="0.112471776561935"
        iyz="7.6527546025921E-19"
        izz="0.111109301926735" />
    </inertial>
    <visual>
      <origin
        xyz="0 0 0"
        rpy="0 0 0" />
      <geometry>
        <mesh
          filename="package://WBR_prototype/meshes/A37_Link.STL" />
      </geometry>
      <material
        name="">
        <color
          rgba="0.898039215686275 0.917647058823529 0.929411764705882 1" />
      </material>
    </visual>
    <collision>
      <origin
        xyz="0 0 0"
        rpy="0 0 0" />
      <geometry>
        <mesh
          filename="package://WBR_prototype/meshes/A37_Link.STL" />
      </geometry>
    </collision>
  </link>
  <joint
    name="A37"
    type="fixed">
    <origin
      xyz="0.1924 0 -0.34992"
      rpy="3.1416 -1.5491 0" />
    <parent
      link="A3_Link" />
    <child
      link="A37_Link" />
    <axis
      xyz="0 0 0" />
  </joint>
  <link
    name="WL_Link">
    <inertial>
      <origin
        xyz="7.28583859910259E-17 0.0249999999999999 -1.11022302462516E-16"
        rpy="0 0 0" />
      <mass
        value="3.01810315038832" />
      <inertia
        ixx="0.0122553300870839"
        ixy="-1.89690408902048E-18"
        ixz="-5.42101086242752E-20"
        iyy="0.0232789295920736"
        iyz="-2.80259652532196E-18"
        izz="0.0122553300870839" />
    </inertial>
    <visual>
      <origin
        xyz="0 0 0"
        rpy="0 0 0" />
      <geometry>
        <mesh
          filename="package://WBR_prototype/meshes/WL_Link.STL" />
      </geometry>
      <material
        name="">
        <color
          rgba="0.298039215686275 0.298039215686275 0.298039215686275 1" />
      </material>
    </visual>
    <collision>
      <origin
        xyz="0 0 0"
        rpy="0 0 0" />
      <geometry>
        <mesh
          filename="package://WBR_prototype/meshes/WL_Link.STL" />
      </geometry>
    </collision>
  </link>
  <joint
    name="WL"
    type="continuous">
    <origin
      xyz="-0.15 0 0"
      rpy="3.1416 -0.80139 0" />
    <parent
      link="A37_Link" />
    <child
      link="WL_Link" />
    <axis
      xyz="0 1 0" />
  </joint>
  <link
    name="A4_Link">
    <inertial>
      <origin
        xyz="0.0123937238930464 0.025 1.38777878078145E-17"
        rpy="0 0 0" />
      <mass
        value="4.58334450236852" />
      <inertia
        ixx="0.00461060976863761"
        ixy="1.20288880669621E-17"
        ixz="-6.26668855696622E-17"
        iyy="0.0604011849476408"
        iyz="6.79934269402883E-19"
        izz="0.0576287318981152" />
    </inertial>
    <visual>
      <origin
        xyz="0 0 0"
        rpy="0 0 0" />
      <geometry>
        <mesh
          filename="package://WBR_prototype/meshes/A4_Link.STL" />
      </geometry>
      <material
        name="">
        <color
          rgba="0.898039215686275 0.917647058823529 0.929411764705882 1" />
      </material>
    </visual>
    <collision>
      <origin
        xyz="0 0 0"
        rpy="0 0 0" />
      <geometry>
        <mesh
          filename="package://WBR_prototype/meshes/A4_Link.STL" />
      </geometry>
    </collision>
  </link>
  <joint
    name="A4"
    type="fixed">
    <origin
      xyz="-0.205 -0.18353 -0.098031"
      rpy="3.1416 0.71225 -1.5708" />
    <parent
      link="base_link" />
    <child
      link="A4_Link" />
    <axis
      xyz="0 0 0" />
  </joint>
  <link
    name="A48_Link">
    <inertial>
      <origin
        xyz="0.109893824662281 0.025 0"
        rpy="0 0 0" />
      <mass
        value="4.99934360485206" />
      <inertia
        ixx="0.00335674361919313"
        ixy="2.82486655469367E-17"
        ixz="-6.52689707836274E-17"
        iyy="0.112471776561935"
        iyz="-4.01023479076307E-19"
        izz="0.111109301926735" />
    </inertial>
    <visual>
      <origin
        xyz="0 0 0"
        rpy="0 0 0" />
      <geometry>
        <mesh
          filename="package://WBR_prototype/meshes/A48_Link.STL" />
      </geometry>
      <material
        name="">
        <color
          rgba="0.898039215686275 0.917647058823529 0.929411764705882 1" />
      </material>
    </visual>
    <collision>
      <origin
        xyz="0 0 0"
        rpy="0 0 0" />
      <geometry>
        <mesh
          filename="package://WBR_prototype/meshes/A48_Link.STL" />
      </geometry>
    </collision>
  </link>
  <joint
    name="A48"
    type="fixed">
    <origin
      xyz="0.1924 0.1 0.34992"
      rpy="3.1416 1.5491 0" />
    <parent
      link="A4_Link" />
    <child
      link="A48_Link" />
    <axis
      xyz="0 0 0" />
  </joint>
</robot>